Workbook

Sheet Products
A1: Source SI No. | B1: Product Category | C1: Partner Company | D1: Country | E1: Product / Model | F1: Planned DIWAN Category Page Path | G1: Website Page Scope | H1: Architecture Updated On | I1: Product Listing Title | J1: Product Listing / Anchor Slug | K1: Short Product Listing Description | L1: Product Listing / Category SEO Support Copy | M1: Product Listing Call to Action | N1: Product Listing Content Status | O1: Product Listing Overview | P1: Key Features & Benefits | Q1: Technical Specifications | R1: Applications & Industries | S1: Primary Image URL | T1: Image Alt Text | U1: Datasheet / Brochure URL | V1: Additional Documents | W1: Related Products | X1: Enquiry Route | Y1: Target SEO Keywords | Z1: Verified Content Source URL | AA1: Source Verified On | AB1: Approval Owner | AC1: Product Listing Content Readiness | AD1: Review Notes | AE1: Additional Image URLs | AF1: Product Video URL | AG1: Commercial Availability Policy | AH1: Lead Time / Delivery Wording | AI1: Public Document Access Rule
A2: 1 | B2: Thermal Analysis | C2: ThermCon Scientific | D2: Germany | E2: STA 1000 / 1600 Simultaneous Thermal Analyzer (TGA + DSC) | F2: /products/thermal-analysis | G2: One page per product category | H2: 46257 | I2: STA 1000 / 1600 Simultaneous Thermal Analyzer (TGA + DSC) | DIWAN Engineering & Technology Company | J2: sta-1000-1600-simultaneous-thermal-analyzer-tga-dsc | K2: The STA 1000 / 1600 combines thermogravimetric and differential scanning calorimetry in one platform for simultaneous mass-change and heat-flow analysis under controlled temperature and atmosphere conditions. | L2: STA 1000 / 1600 Simultaneous Thermal Analyzer (TGA + DSC) from ThermCon Scientific: key capabilities, technical specifications and applications. Request configuration advice and a quotation from DIWAN. | M2: Request technical information or a quote | N2: Draft complete - technical approval and assets pending | O2: ThermCon Scientific's STA 1000 / 1600 is a simultaneous thermal analyzer that records TG and DSC signals in a single test. Its automatic lifting furnace, digital mass-flow control and analysis software support material characterization, stability studies and quality control. | P2: Simultaneous TGA and DSC measurement; automatic lifting furnace; digital mass-flow control; rapid external-water cooling; 0.01 µg weighing resolution; intelligent analysis software; IR-system compatibility. | Q2: Temperature range: room temperature to 1250°C or 1550°C; heating rate: 0.1–100°C/min; cooling rate: -0.1 to -40°C/min; weighing range: 0.01 mg–3 g, expandable to 50 g; DSC range/sensitivity: ±1000 mW / 0.0001 mW; programmable isothermal testing. | R2: Polymers, composites, resins, coatings, metals, ceramics, pharmaceuticals and chemicals; thermal stability, purity, phase transitions, decomposition, composition and reaction-kinetics studies. | S2: https://www.thermconscientific.com/Resim/2ffa86104b_20252165327672.jpg | T2: STA 1000 / 1600 Simultaneous Thermal Analyzer (TGA + DSC) from ThermCon Scientific | V2: No public downloadable brochure identified during review; provide documents on request after manufacturer rights and revision checks. | W2: TGA 1000 / 1600; DSC 600; DTA 1000 / 1600; TC3500S | X2: Thermal Analysis enquiry → website group enquiry form → category owner assignment | Y2: STA 1000 / 1600 Simultaneous Thermal Analyzer (TGA + DSC), Thermal Analysis, ThermCon Scientific, laboratory instrument, DIWAN | Z2: https://www.thermconscientific.com/EN%2C15/sta-1500-simultaneous-thermal-analyzer-tga--dsc.html | AA2: 46257 | AB2: Product Team / Technical Reviewer | AC2: =IF(AND(O2<>"",P2<>"",R2<>"",T2<>"",X2<>"",Y2<>"",Z2<>"",AA2<>"",AB2<>""),IF(AND(Q2<>"",S2<>"",U2<>""),"Ready for approval","Content drafted - assets/specs pending"),IF(COUNTA(O2:AB2)=0,"Not started","In progress")) -> Content drafted - assets/specs pending | AD2: Exact manufacturer product page verified. Product page URL contains 'STA 1500' while the displayed product title is STA 1000 / 1600; confirm naming before publication. Source reviewed 2026-08-23. Primary image and downloadable brochure assets remain open. | AG2: Availability, configuration and commercial supply are subject to confirmation by DIWAN and the manufacturer. | AH2: Lead time is confirmed in the formal quotation; do not publish a fixed delivery commitment. | AI2: Publish manufacturer documents only when public access and reuse are permitted; otherwise provide controlled access on request.
A3: =IF(B3=B2,A2,A2+1) -> 1 | B3: Thermal Analysis | C3: ThermCon Scientific | D3: Germany | E3: TGA 1000 / 1600 Thermogravimetric Analyzer | F3: /products/thermal-analysis | G3: One page per product category | H3: 46257 | I3: TGA 1000 / 1600 Thermogravimetric Analyzer | DIWAN Engineering & Technology Company | J3: tga-1000-1600-thermogravimetric-analyzer | K3: The TGA 1000 / 1600 measures sample mass change during programmed heating and cooling to support thermal stability, decomposition, oxidation and composition analysis. | L3: TGA 1000 / 1600 Thermogravimetric Analyzer from ThermCon Scientific: key capabilities, technical specifications and applications. Request configuration advice and a quotation from DIWAN. | M3: Request technical information or a quote | N3: Draft complete - technical approval and assets pending | O3: ThermCon Scientific's TGA 1000 / 1600 is an automatic-lifting thermogravimetric analyzer for monitoring material mass changes as a function of temperature or time. Controlled gas flow, high-resolution weighing and integrated software support repeatable research and quality-control workflows. | P3: Automatic lifting furnace; high-resolution microbalance; programmed temperature control; automatic atmosphere control; rapid cooling; real-time software analysis; optional coupling with infrared analysis. | Q3: Temperature range: room temperature to 1250°C or 1550°C; temperature resolution: 0.001°C; heating rate: 0.1–100°C/min; cooling rate: -0.1 to -40°C/min; weighing range: 0.01 mg–3 g, expandable to 50 g; weighing resolution: 0.01 µg. | R3: Polymers, chemicals, pharmaceuticals, ceramics, metals and composites; mass-loss, moisture, ash, oxidation, decomposition, thermal stability, purity and composition testing. | S3: https://www.thermconscientific.com/Resim/8268fb1cf5_202432418569359.jpg | T3: TGA 1000 / 1600 Thermogravimetric Analyzer from ThermCon Scientific | V3: No public downloadable brochure identified during review; provide documents on request after manufacturer rights and revision checks. | W3: STA 1000 / 1600; DSC 600; DTA 1000 / 1600; TC3500S | X3: Thermal Analysis enquiry → website group enquiry form → category owner assignment | Y3: TGA 1000 / 1600 Thermogravimetric Analyzer, Thermal Analysis, ThermCon Scientific, laboratory instrument, DIWAN | Z3: https://www.thermconscientific.com/EN%2C20/tga-1000--1600-thermogravimetric-analyzer-tga.html | AA3: 46257 | AB3: Product Team / Technical Reviewer | AC3: =IF(AND(O3<>"",P3<>"",R3<>"",T3<>"",X3<>"",Y3<>"",Z3<>"",AA3<>"",AB3<>""),IF(AND(Q3<>"",S3<>"",U3<>""),"Ready for approval","Content drafted - assets/specs pending"),IF(COUNTA(O3:AB3)=0,"Not started","In progress")) -> Content drafted - assets/specs pending | AD3: Exact manufacturer product page verified; technical approval and publication assets remain required. Source reviewed 2026-08-23. Primary image and downloadable brochure assets remain open. | AG3: Availability, configuration and commercial supply are subject to confirmation by DIWAN and the manufacturer. | AH3: Lead time is confirmed in the formal quotation; do not publish a fixed delivery commitment. | AI3: Publish manufacturer documents only when public access and reuse are permitted; otherwise provide controlled access on request.
A4: =IF(B4=B3,A3,A3+1) -> 1 | B4: Thermal Analysis | C4: ThermCon Scientific | D4: Germany | E4: TC3500S Carbon Black Content Tester | F4: /products/thermal-analysis | G4: One page per product category | H4: 46257 | I4: TC3500S Carbon Black Content Tester | DIWAN Engineering & Technology Company | J4: tc3500s-carbon-black-content-tester | K4: The TC3500S automates carbon-black and ash-content testing for up to four samples with programmed gas switching, touchscreen operation and rapid furnace cooling. | L4: TC3500S Carbon Black Content Tester from ThermCon Scientific: key capabilities, technical specifications and applications. Request configuration advice and a quotation from DIWAN. | M4: Request technical information or a quote | N4: Draft complete - technical approval and assets pending | O4: The ThermCon Scientific TC3500S is a four-position carbon-black content tester designed for controlled heating, gas switching and automatic calculation of carbon-black and ash results. Its open-lid furnace design reduces cooling time between test stages. | P4: Four-sample capacity; one-click carbon-black and ash testing; automatic gas-path switching; 7-inch touchscreen; open-lid rapid-cooling structure; warning and result-printing functions. | Q4: Temperature range: room temperature to 1200°C; temperature sensitivity: 0.1°C; quartz tube: 44 × 600 mm; furnace zone: 45 × 300 mm; two gas paths; cooling from 900°C to room temperature in 20 minutes or less; power: AC 220V, 50/60Hz. | R4: Carbon-black and ash-content testing for polyethylene, polypropylene, cable materials, pipes, rubber compounds and related polymer products. | S4: https://www.thermconscientific.com/Resim/d7cdf5fbde_20255923322294.jpg | T4: TC3500S Carbon Black Content Tester from ThermCon Scientific | V4: No public downloadable brochure identified during review; provide documents on request after manufacturer rights and revision checks. | W4: TGA 1000 / 1600; STA 1000 / 1600; UL94 Flame Chamber | X4: Thermal Analysis enquiry → website group enquiry form → category owner assignment | Y4: TC3500S Carbon Black Content Tester, Thermal Analysis, ThermCon Scientific, laboratory instrument, DIWAN | Z4: https://www.thermconscientific.com/EN%2C119/tc3500s-carbon-black-content-tester.html | AA4: 46257 | AB4: Product Team / Technical Reviewer | AC4: =IF(AND(O4<>"",P4<>"",R4<>"",T4<>"",X4<>"",Y4<>"",Z4<>"",AA4<>"",AB4<>""),IF(AND(Q4<>"",S4<>"",U4<>""),"Ready for approval","Content drafted - assets/specs pending"),IF(COUNTA(O4:AB4)=0,"Not started","In progress")) -> Content drafted - assets/specs pending | AD4: Exact manufacturer product page verified; technical approval and publication assets remain required. Source reviewed 2026-08-23. Primary image and downloadable brochure assets remain open. | AG4: Availability, configuration and commercial supply are subject to confirmation by DIWAN and the manufacturer. | AH4: Lead time is confirmed in the formal quotation; do not publish a fixed delivery commitment. | AI4: Publish manufacturer documents only when public access and reuse are permitted; otherwise provide controlled access on request.
A5: =IF(B5=B4,A4,A4+1) -> 1 | B5: Thermal Analysis | C5: ThermCon Scientific | D5: Germany | E5: DTA 1000 / 1600 Differential Thermal Analyzer | F5: /products/thermal-analysis | G5: One page per product category | H5: 46257 | I5: DTA 1000 / 1600 Differential Thermal Analyzer | DIWAN Engineering & Technology Company | J5: dta-1000-1600-differential-thermal-analyzer | K5: The DTA 1000 / 1600 measures temperature differences between a sample and reference during programmed heating for phase-transition and reaction analysis at high temperature. | L5: DTA 1000 / 1600 Differential Thermal Analyzer from ThermCon Scientific: key capabilities, technical specifications and applications. Request configuration advice and a quotation from DIWAN. | M5: Request technical information or a quote | N5: Draft complete - technical approval and assets pending | O5: ThermCon Scientific's DTA 1000 / 1600 is a differential thermal analyzer with programmable temperature control, automatic atmosphere switching and real-time software analysis. The platform is designed for high-temperature studies where endothermic and exothermic events must be identified. | P5: ARM-based control; 7-inch color touchscreen; USB two-way communication; nickel-chromium sensor; programmable temperature control; automatic atmosphere switching; one-button calibration; live graph collection and analysis. | Q5: Temperature range: room temperature to 1250°C or 1550°C; signal range: 0 to ±2000 µV, expandable; sensitivity: 0.01 µV; heating rate: 0.1–100°C/min; temperature resolution: 0.01°C; temperature accuracy and repeatability: ±0.1°C. | R5: Ceramics, glass, minerals, metals, chemicals, catalysts and other materials requiring phase-transition, oxidation, decomposition or reaction-temperature analysis. | S5: https://www.thermconscientific.com/Resim/a05b35b702_2025585556764.jpg | T5: DTA 1000 / 1600 Differential Thermal Analyzer from ThermCon Scientific | V5: No public downloadable brochure identified during review; provide documents on request after manufacturer rights and revision checks. | W5: STA 1000 / 1600; TGA 1000 / 1600; DSC 600 | X5: Thermal Analysis enquiry → website group enquiry form → category owner assignment | Y5: DTA 1000 / 1600 Differential Thermal Analyzer, Thermal Analysis, ThermCon Scientific, laboratory instrument, DIWAN | Z5: https://www.thermconscientific.com/EN%2C121/dta-1000--1600-differential-thermal-analyzer.html | AA5: 46257 | AB5: Product Team / Technical Reviewer | AC5: =IF(AND(O5<>"",P5<>"",R5<>"",T5<>"",X5<>"",Y5<>"",Z5<>"",AA5<>"",AB5<>""),IF(AND(Q5<>"",S5<>"",U5<>""),"Ready for approval","Content drafted - assets/specs pending"),IF(COUNTA(O5:AB5)=0,"Not started","In progress")) -> Content drafted - assets/specs pending | AD5: Exact manufacturer product page verified; technical approval and publication assets remain required. Source reviewed 2026-08-23. Primary image and downloadable brochure assets remain open. | AG5: Availability, configuration and commercial supply are subject to confirmation by DIWAN and the manufacturer. | AH5: Lead time is confirmed in the formal quotation; do not publish a fixed delivery commitment. | AI5: Publish manufacturer documents only when public access and reuse are permitted; otherwise provide controlled access on request.
A6: =IF(B6=B5,A5,A5+1) -> 1 | B6: Thermal Analysis | C6: ThermCon Scientific | D6: Germany | E6: DSC 600 High-Precision Differential Scanning Calorimeter | F6: /products/thermal-analysis | G6: One page per product category | H6: 46257 | I6: DSC 600 High-Precision Differential Scanning Calorimeter | DIWAN Engineering & Technology Company | J6: dsc-600-high-precision-differential-scanning-calorimeter | K6: The DSC 600 is a high-precision differential scanning calorimeter for measuring melting, crystallization, glass transition, curing and oxidation-induction behavior. | L6: DSC 600 High-Precision Differential Scanning Calorimeter from ThermCon Scientific: key capabilities, technical specifications and applications. Request configuration advice and a quotation from DIWAN. | M6: Request technical information or a quote | N6: Draft complete - technical approval and assets pending | O6: The ThermCon Scientific DSC 600 measures heat-flow changes associated with physical and chemical transitions. Its high sensitivity, wide temperature options and touchscreen control support research, formulation work and routine quality control. | P6: High measurement sensitivity; stable baseline; strong repeatability; multiple cooling options; 7-inch touchscreen; programmable heating and cooling; three gas-control channels; real-time software analysis. | Q6: Temperature options extend from approximately -70°C to 600°C depending on configuration; sensitivity: 0.1 µW; noise: 0.001 mW; heating rate: 0.1–100°C/min; cooling rate: -0.1 to -60°C/min; three gas channels. | R6: Plastics, polymers, chemicals, food, pharmaceuticals, academic research, metrology and quality control; Tg, melting, crystallization, enthalpy, curing and OIT testing. | S6: https://www.thermconscientific.com/Resim/aa8f8e8e7d_2024324185816509.jpg | T6: DSC 600 High-Precision Differential Scanning Calorimeter from ThermCon Scientific | V6: No public downloadable brochure identified during review; provide documents on request after manufacturer rights and revision checks. | W6: DSC-600A; STA 1000 / 1600; TGA 1000 / 1600 | X6: Thermal Analysis enquiry → website group enquiry form → category owner assignment | Y6: DSC 600 High-Precision Differential Scanning Calorimeter, Thermal Analysis, ThermCon Scientific, laboratory instrument, DIWAN | Z6: https://www.thermconscientific.com/EN%2C24/dsc-600--high-precision-differential-scanning-calorimeter.html | AA6: 46257 | AB6: Product Team / Technical Reviewer | AC6: =IF(AND(O6<>"",P6<>"",R6<>"",T6<>"",X6<>"",Y6<>"",Z6<>"",AA6<>"",AB6<>""),IF(AND(Q6<>"",S6<>"",U6<>""),"Ready for approval","Content drafted - assets/specs pending"),IF(COUNTA(O6:AB6)=0,"Not started","In progress")) -> Content drafted - assets/specs pending | AD6: Exact manufacturer product page verified; configuration-specific temperature range must be confirmed during quotation. Source reviewed 2026-08-23. Primary image and downloadable brochure assets remain open. | AG6: Availability, configuration and commercial supply are subject to confirmation by DIWAN and the manufacturer. | AH6: Lead time is confirmed in the formal quotation; do not publish a fixed delivery commitment. | AI6: Publish manufacturer documents only when public access and reuse are permitted; otherwise provide controlled access on request.
A7: =IF(B7=B6,A6,A6+1) -> 1 | B7: Thermal Analysis | C7: ThermCon Scientific | D7: Germany | E7: DSC-600A Differential Scanning Calorimeter | F7: /products/thermal-analysis | G7: One page per product category | H7: 46257 | I7: DSC-600A Differential Scanning Calorimeter | DIWAN Engineering & Technology Company | J7: dsc-600a-differential-scanning-calorimeter | K7: The DSC-600A adds automated batch handling to DSC testing, allowing up to 40 samples to be processed with reduced operator intervention. | L7: DSC-600A Differential Scanning Calorimeter from ThermCon Scientific: key capabilities, technical specifications and applications. Request configuration advice and a quotation from DIWAN. | M7: Request technical information or a quote | N7: Draft complete - technical approval and assets pending | O7: The ThermCon Scientific DSC-600A is an automatic differential scanning calorimeter designed for repetitive laboratory workflows. A multi-position sample changer automates batch testing while retaining the DSC platform's transition, enthalpy, curing and oxidation-induction capabilities. | P7: Automatic sample changer for up to 40 samples; unattended batch testing; high-sensitivity DSC measurement; programmable temperature control; touchscreen operation; software-based data capture and analysis. | Q7: Automatic capacity: up to 40 samples; DSC functions and temperature configurations align with the DSC 600 platform and require final configuration confirmation; model-specific cooling and gas-control options are selected at quotation. | R7: High-throughput polymer, chemical, pharmaceutical, food and quality-control laboratories performing repetitive DSC measurements. | S7: https://www.thermconscientific.com/Resim/a637ae4c86_20255922813016.jpg | T7: DSC-600A Differential Scanning Calorimeter from ThermCon Scientific | V7: No public downloadable brochure identified during review; provide documents on request after manufacturer rights and revision checks. | W7: DSC 600; STA 1000 / 1600; TGA 1000 / 1600 | X7: Thermal Analysis enquiry → website group enquiry form → category owner assignment | Y7: DSC-600A Differential Scanning Calorimeter, Thermal Analysis, ThermCon Scientific, laboratory instrument, DIWAN | Z7: https://www.thermconscientific.com/EN%2C212/dsc---600a-differential-scanning-calorimeter.html | AA7: 46257 | AB7: Product Team / Technical Reviewer | AC7: =IF(AND(O7<>"",P7<>"",R7<>"",T7<>"",X7<>"",Y7<>"",Z7<>"",AA7<>"",AB7<>""),IF(AND(Q7<>"",S7<>"",U7<>""),"Ready for approval","Content drafted - assets/specs pending"),IF(COUNTA(O7:AB7)=0,"Not started","In progress")) -> Content drafted - assets/specs pending | AD7: Exact manufacturer product page verified; final technical configuration must be approved before publication. Source reviewed 2026-08-23. Primary image and downloadable brochure assets remain open. | AG7: Availability, configuration and commercial supply are subject to confirmation by DIWAN and the manufacturer. | AH7: Lead time is confirmed in the formal quotation; do not publish a fixed delivery commitment. | AI7: Publish manufacturer documents only when public access and reuse are permitted; otherwise provide controlled access on request.
A8: =IF(B8=B7,A7,A7+1) -> 2 | B8: Thermal Conductivity | C8: ThermCon Scientific | D8: Germany | E8: HFM50/300 Thermal Conductivity Tester | F8: /products/thermal-conductivity | G8: One page per product category | H8: 46257 | I8: HFM50/300 Thermal Conductivity Tester | DIWAN Engineering & Technology Company | J8: hfm50-300-thermal-conductivity-tester | K8: The HFM50/300 uses the heat-flow method to measure thermal conductivity, diffusivity and thermal resistance of small low- and medium-conductivity samples. | L8: HFM50/300 Thermal Conductivity Tester from ThermCon Scientific: key capabilities, technical specifications and applications. Request configuration advice and a quotation from DIWAN. | M8: Request technical information or a quote | N8: Draft complete - technical approval and assets pending | O8: ThermCon Scientific's HFM50/300 is a computer-controlled heat-flow instrument for compact samples, thin materials and interface products. Automatic plate positioning and thickness measurement simplify calibrated testing and data management. | P8: Automatic plate movement; automatic sample-thickness measurement; small-sample testing; multilayer thin-film method; programmable temperature control; stored calibration and test data; automatic analysis software. | Q8: Temperature options: room temperature to 40°C, 200°C or 300°C; sample: 30 mm diameter or 30 × 30 mm, thickness 0.1–20 mm; conductivity range: 0.010–45 W/m·K; thermal resistance: 0.000005–0.05 m²·K/W; accuracy: within ±3%; force: 0–500 N. | R8: Polymers, ceramics, insulation, composites, non-metallic materials, thermal interface pads, silicone grease and thin films; standards include ASTM E1530, ASTM C518, ISO 8301 and DIN EN 12667. | S8: https://www.thermconscientific.com/Resim/d6d050df5e_2024326131842234.jpg | T8: HFM50/300 Thermal Conductivity Tester from ThermCon Scientific | V8: No public downloadable brochure identified during review; provide documents on request after manufacturer rights and revision checks. | W8: HFM 300/600; HFM1600; THS 200; TPS 500 | X8: Thermal Conductivity enquiry → website group enquiry form → category owner assignment | Y8: HFM50/300 Thermal Conductivity Tester, Thermal Conductivity, ThermCon Scientific, laboratory instrument, DIWAN | Z8: https://www.thermconscientific.com/EN%2C33/hfm50300-thermal-conductivity-tester.html | AA8: 46257 | AB8: Product Team / Technical Reviewer | AC8: =IF(AND(O8<>"",P8<>"",R8<>"",T8<>"",X8<>"",Y8<>"",Z8<>"",AA8<>"",AB8<>""),IF(AND(Q8<>"",S8<>"",U8<>""),"Ready for approval","Content drafted - assets/specs pending"),IF(COUNTA(O8:AB8)=0,"Not started","In progress")) -> Content drafted - assets/specs pending | AD8: Exact manufacturer product page verified; technical approval and publication assets remain required. Source reviewed 2026-08-23. Primary image and downloadable brochure assets remain open. | AG8: Availability, configuration and commercial supply are subject to confirmation by DIWAN and the manufacturer. | AH8: Lead time is confirmed in the formal quotation; do not publish a fixed delivery commitment. | AI8: Publish manufacturer documents only when public access and reuse are permitted; otherwise provide controlled access on request.
A9: =IF(B9=B8,A8,A8+1) -> 2 | B9: Thermal Conductivity | C9: ThermCon Scientific | D9: Germany | E9: LFA 1600 Laser Flash Thermal Conductivity & Diffusivity Tester | F9: /products/thermal-conductivity | G9: One page per product category | H9: 46257 | I9: LFA 1600 Laser Flash Thermal Conductivity & Diffusivity Tester | DIWAN Engineering & Technology Company | J9: lfa-1600-laser-flash-thermal-conductivity-and-diffusivity-tester | K9: The LFA 1600 uses laser-flash heating and infrared detection to determine thermal diffusivity and calculate thermal conductivity across a broad material and temperature range. | L9: LFA 1600 Laser Flash Thermal Conductivity & Diffusivity Tester from ThermCon Scientific: key capabilities, technical specifications and applications. Request configuration advice and a quotation from DIWAN. | M9: Request technical information or a quote | N9: Draft complete - technical approval and assets pending | O9: The ThermCon Scientific LFA 1600 is a laser-flash thermal-property analyzer for rapid, non-contact measurement of thermal diffusivity. With density and heat-capacity inputs, the software supports thermal-conductivity calculation for high-performance materials. | P9: Laser-flash method; infrared temperature detection; high-temperature configurations; broad diffusivity and conductivity ranges; fast transient measurement; software calculation and reporting. | Q9: Temperature options: room temperature to 1000°C, 1400°C or 1600°C; sample diameter: 10–25 mm or square samples at least 10 × 10 mm; thickness: 0.1–10 mm; diffusivity: 0.01–1000 mm²/s; conductivity: 0.1–2000 W/m·K; accuracy: ±4%; repeatability: ±3%. | R9: Metals, alloys, diamond, ceramics, graphite, carbon fiber, plastics, polymers and composite materials for thermal-management and high-temperature research. | S9: https://www.thermconscientific.com/Resim/a161863b18_20244417457706.jpg | T9: LFA 1600 Laser Flash Thermal Conductivity & Diffusivity Tester from ThermCon Scientific | V9: No public downloadable brochure identified during review; provide documents on request after manufacturer rights and revision checks. | W9: HFM1600; HFM50/300; THS 200; TPS 500 | X9: Thermal Conductivity enquiry → website group enquiry form → category owner assignment | Y9: LFA 1600 Laser Flash Thermal Conductivity & Diffusivity Tester, Thermal Conductivity, ThermCon Scientific, laboratory instrument, DIWAN | Z9: https://www.thermconscientific.com/EN%2C34/lfa-1600-laser-flash-thermal-conductivity-diffusivity-tester.html | AA9: 46257 | AB9: Product Team / Technical Reviewer | AC9: =IF(AND(O9<>"",P9<>"",R9<>"",T9<>"",X9<>"",Y9<>"",Z9<>"",AA9<>"",AB9<>""),IF(AND(Q9<>"",S9<>"",U9<>""),"Ready for approval","Content drafted - assets/specs pending"),IF(COUNTA(O9:AB9)=0,"Not started","In progress")) -> Content drafted - assets/specs pending | AD9: Exact manufacturer URL verified. The product URL/title states LFA 1600, while part of the official page text references LFA 1000; confirm the model designation before publication. Source reviewed 2026-08-23. Primary image and downloadable brochure assets remain open. | AG9: Availability, configuration and commercial supply are subject to confirmation by DIWAN and the manufacturer. | AH9: Lead time is confirmed in the formal quotation; do not publish a fixed delivery commitment. | AI9: Publish manufacturer documents only when public access and reuse are permitted; otherwise provide controlled access on request.
A10: =IF(B10=B9,A9,A9+1) -> 2 | B10: Thermal Conductivity | C10: ThermCon Scientific | D10: Germany | E10: Tuber 200 Pipe Insulation Thermal Conductivity Tester | F10: /products/thermal-conductivity | G10: One page per product category | H10: 46257 | I10: Tuber 200 Pipe Insulation Thermal Conductivity Tester | DIWAN Engineering & Technology Company | J10: tuber-200-pipe-insulation-thermal-conductivity-tester | K10: The Tuber 200 measures thermal conductivity of cylindrical pipe-insulation systems using a guarded steady-state method for service temperatures up to 200°C. | L10: Tuber 200 Pipe Insulation Thermal Conductivity Tester from ThermCon Scientific: key capabilities, technical specifications and applications. Request configuration advice and a quotation from DIWAN. | M10: Request technical information or a quote | N10: Draft complete - technical approval and assets pending | O10: ThermCon Scientific's Tuber 200 is designed for pipe and tubular insulation where flat-sample instruments are not suitable. The system evaluates heat transfer through complete cylindrical insulation sections under controlled temperature conditions. | P10: Purpose-built cylindrical test geometry; steady-state heat-flow measurement; programmed temperature control; repeatable pipe-insulation testing; software-supported data acquisition. | Q10: Temperature range: room temperature to 200°C; accuracy: ±3%; repeatability: ±2%; temperature control: ±0.5°C; sample inner diameter: 18–89 mm; outer diameter: 50–249 mm; sample length: 500 mm; reference standards include ISO/DIS 8497 and GB 10296. | R10: Rubber and plastic pipe insulation, mineral and glass wool tubes, fiberglass pipe sections and industrial/building thermal-insulation systems. | S10: https://www.thermconscientific.com/Resim/8ffcfa83e7_2024441821136.jpg | T10: Tuber 200 Pipe Insulation Thermal Conductivity Tester from ThermCon Scientific | V10: No public downloadable brochure identified during review; provide documents on request after manufacturer rights and revision checks. | W10: HFM 300/600; HFM50/300; HFM1600 | X10: Thermal Conductivity enquiry → website group enquiry form → category owner assignment | Y10: Tuber 200 Pipe Insulation Thermal Conductivity Tester, Thermal Conductivity, ThermCon Scientific, laboratory instrument, DIWAN | Z10: https://www.thermconscientific.com/EN%2C36/tuber-200-pipe-insulation-thermal-conductivity-tester.html | AA10: 46257 | AB10: Product Team / Technical Reviewer | AC10: =IF(AND(O10<>"",P10<>"",R10<>"",T10<>"",X10<>"",Y10<>"",Z10<>"",AA10<>"",AB10<>""),IF(AND(Q10<>"",S10<>"",U10<>""),"Ready for approval","Content drafted - assets/specs pending"),IF(COUNTA(O10:AB10)=0,"Not started","In progress")) -> Content drafted - assets/specs pending | AD10: Exact manufacturer product page verified; technical approval and publication assets remain required. Source reviewed 2026-08-23. Primary image and downloadable brochure assets remain open. | AG10: Availability, configuration and commercial supply are subject to confirmation by DIWAN and the manufacturer. | AH10: Lead time is confirmed in the formal quotation; do not publish a fixed delivery commitment. | AI10: Publish manufacturer documents only when public access and reuse are permitted; otherwise provide controlled access on request.
A11: =IF(B11=B10,A10,A10+1) -> 2 | B11: Thermal Conductivity | C11: ThermCon Scientific | D11: Germany | E11: SB-850 Seebeck and Electrical Resistivity Test Device | F11: /products/thermal-conductivity | G11: One page per product category | H11: 46257 | I11: SB-850 Seebeck and Electrical Resistivity Test Device | DIWAN Engineering & Technology Company | J11: sb-850-seebeck-and-electrical-resistivity-test-device | K11: The SB-850 measures Seebeck coefficient and electrical resistivity of thermoelectric materials under controlled temperatures up to 850°C. | L11: SB-850 Seebeck and Electrical Resistivity Test Device from ThermCon Scientific: key capabilities, technical specifications and applications. Request configuration advice and a quotation from DIWAN. | M11: Request technical information or a quote | N11: Draft complete - technical approval and assets pending | O11: ThermCon Scientific's SB-850 combines Seebeck-coefficient and resistivity measurements for thermoelectric material development. The system applies controlled temperature gradients and current measurement to characterize metals and semiconductors. | P11: Combined Seebeck and resistivity testing; controlled high-temperature operation; programmable current; software acquisition; suitable for research-scale thermoelectric specimens. | Q11: Temperature range: room temperature to 850°C; temperature resolution: 0.001°C; control stability: ±0.25 K; current: 0–220 mA; Seebeck range: 0.5 µV/K–25 V/K; resistivity: 0.2 µΩ·mm–2.5 kΩ·mm; repeatability: ±3%; sample: 4 × 4 × 20 to 8 × 8 × 30 mm. | R11: Thermoelectric metals, alloys, semiconductors, energy-conversion materials and academic or industrial materials research. | S11: https://www.thermconscientific.com/Resim/0a26afe960_20244418445147.jpg | T11: SB-850 Seebeck and Electrical Resistivity Test Device from ThermCon Scientific | V11: No public downloadable brochure identified during review; provide documents on request after manufacturer rights and revision checks. | W11: LFA 1600; THS 200; TPS 500 | X11: Thermal Conductivity enquiry → website group enquiry form → category owner assignment | Y11: SB-850 Seebeck and Electrical Resistivity Test Device, Thermal Conductivity, ThermCon Scientific, laboratory instrument, DIWAN | Z11: https://www.thermconscientific.com/EN%2C37/sb-850-seebeck-and-electrical-resistivity-test-device.html | AA11: 46257 | AB11: Product Team / Technical Reviewer | AC11: =IF(AND(O11<>"",P11<>"",R11<>"",T11<>"",X11<>"",Y11<>"",Z11<>"",AA11<>"",AB11<>""),IF(AND(Q11<>"",S11<>"",U11<>""),"Ready for approval","Content drafted - assets/specs pending"),IF(COUNTA(O11:AB11)=0,"Not started","In progress")) -> Content drafted - assets/specs pending | AD11: Exact manufacturer product page verified; technical approval and publication assets remain required. Source reviewed 2026-08-23. Primary image and downloadable brochure assets remain open. | AG11: Availability, configuration and commercial supply are subject to confirmation by DIWAN and the manufacturer. | AH11: Lead time is confirmed in the formal quotation; do not publish a fixed delivery commitment. | AI11: Publish manufacturer documents only when public access and reuse are permitted; otherwise provide controlled access on request.
A12: =IF(B12=B11,A11,A11+1) -> 2 | B12: Thermal Conductivity | C12: ThermCon Scientific | D12: Germany | E12: THS 200 Thermal Conductivity Tester | F12: /products/thermal-conductivity | G12: One page per product category | H12: 46257 | I12: THS 200 Thermal Conductivity Tester | DIWAN Engineering & Technology Company | J12: ths-200-thermal-conductivity-tester | K12: The THS 200 is an automated transient hot-source instrument for rapid thermal-conductivity testing of solids, liquids, powders, pastes, films and insulation materials. | L12: THS 200 Thermal Conductivity Tester from ThermCon Scientific: key capabilities, technical specifications and applications. Request configuration advice and a quotation from DIWAN. | M12: Request technical information or a quote | N12: Draft complete - technical approval and assets pending | O12: The ThermCon Scientific THS 200 applies a transient heat source and monitors the resulting temperature response to calculate thermal conductivity. Automatic power adjustment, dual probes and software analysis support fast tests across diverse sample forms. | P12: Transient hot-source method; fully automatic comparison and power adjustment; dual high-precision probes; bidirectional software/device control; direct conductivity calculation; measurement in 160 seconds or less. | Q12: Conductivity range: 0.00001–50 W/m·K; temperature range: -30°C to 200°C; accuracy: 0.001 W/m·K; repeatability error: 1% or less; two probes; test time: 160 seconds or less; 18 ml holder for liquids and powders. | R12: Bulk solids, metals, liquids, powders, colloids, pastes, films, alloys, composites and thermal-insulation materials. | S12: https://www.thermconscientific.com/Resim/bb3630583e_202432613258124.jpg | T12: THS 200 Thermal Conductivity Tester from ThermCon Scientific | V12: No public downloadable brochure identified during review; provide documents on request after manufacturer rights and revision checks. | W12: TPS 500; HFM50/300; LFA 1600 | X12: Thermal Conductivity enquiry → website group enquiry form → category owner assignment | Y12: THS 200 Thermal Conductivity Tester, Thermal Conductivity, ThermCon Scientific, laboratory instrument, DIWAN | Z12: https://www.thermconscientific.com/EN%2C38/ths-200-thermal-conductivity-tester.html | AA12: 46257 | AB12: Product Team / Technical Reviewer | AC12: =IF(AND(O12<>"",P12<>"",R12<>"",T12<>"",X12<>"",Y12<>"",Z12<>"",AA12<>"",AB12<>""),IF(AND(Q12<>"",S12<>"",U12<>""),"Ready for approval","Content drafted - assets/specs pending"),IF(COUNTA(O12:AB12)=0,"Not started","In progress")) -> Content drafted - assets/specs pending | AD12: Exact manufacturer product page verified; technical approval and publication assets remain required. Source reviewed 2026-08-23. Primary image and downloadable brochure assets remain open. | AG12: Availability, configuration and commercial supply are subject to confirmation by DIWAN and the manufacturer. | AH12: Lead time is confirmed in the formal quotation; do not publish a fixed delivery commitment. | AI12: Publish manufacturer documents only when public access and reuse are permitted; otherwise provide controlled access on request.
A13: =IF(B13=B12,A12,A12+1) -> 2 | B13: Thermal Conductivity | C13: ThermCon Scientific | D13: Germany | E13: TPS 500 Thermal Conductivity Tester (Transient Plane Heat Source) | F13: /products/thermal-conductivity | G13: One page per product category | H13: 46257 | I13: TPS 500 Thermal Conductivity Tester (Transient Plane Heat Source) | DIWAN Engineering & Technology Company | J13: tps-500-thermal-conductivity-tester-transient-plane-heat-source | K13: The TPS 500 uses transient plane-source technology to measure thermal conductivity, diffusivity and heat capacity across solids, powders, films and coatings. | L13: TPS 500 Thermal Conductivity Tester (Transient Plane Heat Source) from ThermCon Scientific: key capabilities, technical specifications and applications. Request configuration advice and a quotation from DIWAN. | M13: Request technical information or a quote | N13: Draft complete - technical approval and assets pending | O13: ThermCon Scientific's TPS 500 is a flexible transient plane heat-source platform for rapid thermal-property measurement. Multiple probes and test modules support bulk, thin-film, anisotropic, single-sided and specific-heat workflows with minimal sample preparation. | P13: Transient plane-source method; fast testing in seconds; reduced sensitivity to contact resistance; minimal sample preparation; multiple test modules; automatic analysis and Excel export. | Q13: Conductivity range: 0.003–500 W/m·K; temperature options: room temperature to 40°C, 200°C or 1000°C; probe diameters: 7.5 mm and 15 mm; sample thickness: 0.05–10 mm; accuracy: ±5%; reproducibility: ±3%; USB data transfer. | R13: Metals, alloys, ceramics, ores, composites, silicon wafers, polymers, binders, paper, textiles, printed circuit boards, powders, films and coatings. | S13: https://www.thermconscientific.com/Resim/8c7535927c_202562492630719.jpg | T13: TPS 500 Thermal Conductivity Tester (Transient Plane Heat Source) from ThermCon Scientific | V13: No public downloadable brochure identified during review; provide documents on request after manufacturer rights and revision checks. | W13: THS 200; HFM50/300; LFA 1600; HFM 300/600 | X13: Thermal Conductivity enquiry → website group enquiry form → category owner assignment | Y13: TPS 500 Thermal Conductivity Tester (Transient Plane Heat Source), Thermal Conductivity, ThermCon Scientific, laboratory instrument, DIWAN | Z13: https://www.thermconscientific.com/EN%2C130/tps-500-thermal-conductivity-tester-transient-plane-heat-source.html | AA13: 46257 | AB13: Product Team / Technical Reviewer | AC13: =IF(AND(O13<>"",P13<>"",R13<>"",T13<>"",X13<>"",Y13<>"",Z13<>"",AA13<>"",AB13<>""),IF(AND(Q13<>"",S13<>"",U13<>""),"Ready for approval","Content drafted - assets/specs pending"),IF(COUNTA(O13:AB13)=0,"Not started","In progress")) -> Content drafted - assets/specs pending | AD13: Exact manufacturer product page verified; technical approval and publication assets remain required. Source reviewed 2026-08-23. Primary image and downloadable brochure assets remain open. | AG13: Availability, configuration and commercial supply are subject to confirmation by DIWAN and the manufacturer. | AH13: Lead time is confirmed in the formal quotation; do not publish a fixed delivery commitment. | AI13: Publish manufacturer documents only when public access and reuse are permitted; otherwise provide controlled access on request.
A14: =IF(B14=B13,A13,A13+1) -> 2 | B14: Thermal Conductivity | C14: ThermCon Scientific | D14: Germany | E14: HFM 300/600 Series Heat Flow Meter | F14: /products/thermal-conductivity | G14: One page per product category | H14: 46257 | I14: HFM 300/600 Series Heat Flow Meter | DIWAN Engineering & Technology Company | J14: hfm-300-600-series-heat-flow-meter | K14: The HFM 300/600 Series measures thermal conductivity and R-value of full-size insulation and building-material specimens using a calibrated heat-flow-meter method. | L14: HFM 300/600 Series Heat Flow Meter from ThermCon Scientific: key capabilities, technical specifications and applications. Request configuration advice and a quotation from DIWAN. | M14: Request technical information or a quote | N14: Draft complete - technical approval and assets pending | O14: ThermCon Scientific's HFM 300/600 Series is designed for larger insulation, construction and panel samples. Guarded plates, automatic thickness measurement and environmental compensation support repeatable conductivity and thermal-resistance testing. | P14: Large-format heat-flow-meter method; automatic sample-thickness measurement; guarded measurement area; controlled plate temperatures; calibration and compensation functions; automatic test and reporting software. | Q14: HFM 300 sample area: up to 300 × 300 mm with thickness 5–100 mm; HFM 600 sample area: up to 600 × 600 mm with thickness up to 200 mm; supports ASTM C518, ISO 8301, DIN EN 12667, EN 12664/12939 and related standards. | R14: EPS, XPS, PUR/PIR, mineral wool, rock wool, glass wool, ceramic fiber, vacuum panels, sandwich panels, fiberboard, concrete, drywall and composite building products. | S14: https://www.thermconscientific.com/Resim/122153bf0a_20252141426213.jpg | T14: HFM 300/600 Series Heat Flow Meter from ThermCon Scientific | V14: No public downloadable brochure identified during review; provide documents on request after manufacturer rights and revision checks. | W14: HFM50/300; Tuber 200; HFM1600 | X14: Thermal Conductivity enquiry → website group enquiry form → category owner assignment | Y14: HFM 300/600 Series Heat Flow Meter, Thermal Conductivity, ThermCon Scientific, laboratory instrument, DIWAN | Z14: https://www.thermconscientific.com/EN%2C221/hfm-300600-series-heat-flow-meter.html | AA14: 46257 | AB14: Product Team / Technical Reviewer | AC14: =IF(AND(O14<>"",P14<>"",R14<>"",T14<>"",X14<>"",Y14<>"",Z14<>"",AA14<>"",AB14<>""),IF(AND(Q14<>"",S14<>"",U14<>""),"Ready for approval","Content drafted - assets/specs pending"),IF(COUNTA(O14:AB14)=0,"Not started","In progress")) -> Content drafted - assets/specs pending | AD14: Exact manufacturer product page verified; confirm configuration-specific measurement range and plate-temperature options before publication. Source reviewed 2026-08-23. Primary image and downloadable brochure assets remain open. | AG14: Availability, configuration and commercial supply are subject to confirmation by DIWAN and the manufacturer. | AH14: Lead time is confirmed in the formal quotation; do not publish a fixed delivery commitment. | AI14: Publish manufacturer documents only when public access and reuse are permitted; otherwise provide controlled access on request.
... A17: =IF(B17=B16,A16,A16+1) -> 3 | B17: Dilatometry | C17: ThermCon Scientific | D17: Germany | E17: DIL Optical Sintering Point Tester (Optical Dilatometer) | F17: /products/dilatometry | G17: One page per product category | H17: 46257 | I17: DIL Optical Sintering Point Tester (Optical Dilatometer) | DIWAN Engineering & Technology Company | J17: dil-optical-sintering-point-tester-optical-dilatometer | K17: The DIL Optical uses high-temperature image analysis to measure sintering, softening, melting, refractoriness and contact-angle behavior without contacting the sample. | L17: DIL Optical Sintering Point Tester (Optical Dilatometer) from ThermCon Scientific: key capabilities, technical specifications and applications. Request configuration advice and a quotation from DIWAN. | M17: Request technical information or a quote | N17: Draft complete - technical approval and assets pending | O17: The ThermCon Scientific DIL Optical is a non-contact optical dilatometer and high-temperature microscopy system. A transmitted-image setup tracks specimen shape and dimensional change during heating, making it suitable for materials that soften, deform or melt. | P17: Non-contact optical measurement; high-temperature transmitted imaging; automated shape and dimensional analysis; programmable heating; software image capture; suitable for softening and melting materials. | Q17: Temperature range: approximately 30–1600°C; heating rate: 0.1–80°C/min; high-resolution optical imaging; nitrogen atmosphere and water-cooling provisions; sample dimensions and optical configuration require final confirmation. | R17: Sand, glass, compounds, refractories, ceramic raw materials and metals; sintering point, melting point, refractoriness, deformation and surface contact-angle studies. | S17: https://www.thermconscientific.com/Resim/93c33819fc_202443131745108.jpg | T17: DIL Optical Sintering Point Tester (Optical Dilatometer) from ThermCon Scientific | V17: No public downloadable brochure identified during review; provide documents on request after manufacturer rights and revision checks. | W17: DIL Series; DIL-D; DIL-C | X17: Dilatometry enquiry → website group enquiry form → category owner assignment | Y17: DIL Optical Sintering Point Tester (Optical Dilatometer), Dilatometry, ThermCon Scientific, laboratory instrument, DIWAN | Z17: https://www.thermconscientific.com/EN%2C109/dil-optical---sintering-point-tester-optical-dilatometer.html | AA17: 46257 | AB17: Product Team / Technical Reviewer | AC17: =IF(AND(O17<>"",P17<>"",R17<>"",T17<>"",X17<>"",Y17<>"",Z17<>"",AA17<>"",AB17<>""),IF(AND(Q17<>"",S17<>"",U17<>""),"Ready for approval","Content drafted - assets/specs pending"),IF(COUNTA(O17:AB17)=0,"Not started","In progress")) -> Content drafted - assets/specs pending | AD17: Exact manufacturer product page verified; confirm final optical specification and sample geometry before publication. Source reviewed 2026-08-23. Primary image and downloadable brochure assets remain open. | AG17: Availability, configuration and commercial supply are subject to confirmation by DIWAN and the manufacturer. | AH17: Lead time is confirmed in the formal quotation; do not publish a fixed delivery commitment. | AI17: Publish manufacturer documents only when public access and reuse are permitted; otherwise provide controlled access on request.
A18: =IF(B18=B17,A17,A17+1) -> 3 | B18: Dilatometry | C18: ThermCon Scientific | D18: Germany | E18: DIL-Q Quenching Deformation Dilatometer | F18: /products/dilatometry | G18: One page per product category | H18: 46257 | I18: DIL-Q Quenching Deformation Dilatometer | DIWAN Engineering & Technology Company | J18: dil-q-quenching-deformation-dilatometer | K18: The DIL-Q is ThermCon Scientific's quenching-deformation dilatometer line for studying dimensional change during controlled heating, cooling and quench cycles. | L18: DIL-Q Quenching Deformation Dilatometer from ThermCon Scientific: key capabilities, technical specifications and applications. Request configuration advice and a quotation from DIWAN. | M18: Request technical information or a quote | N18: Draft complete - technical approval and assets pending | O18: ThermCon Scientific lists the DIL-Q as a quenching deformation dilatometer within its dilatometry portfolio. The product is intended for temperature-dependent deformation and transformation studies where rapid cooling or quenching behavior is important. | P18: Quenching-deformation measurement; programmed thermal cycles; dimensional-change monitoring; application-specific atmosphere and cooling configuration subject to technical confirmation. | R18: Metals, alloys, heat-treatment research, phase-transformation studies and materials-development laboratories. | S18: https://www.thermconscientific.com/Resim/c2a83a2fe4_20244313181731.jpg | T18: DIL-Q Quenching Deformation Dilatometer from ThermCon Scientific | V18: No public downloadable brochure identified during review; provide documents on request after manufacturer rights and revision checks. | W18: DIL-D; DIL Series; DIL-C | X18: Dilatometry enquiry → website group enquiry form → category owner assignment | Y18: DIL-Q Quenching Deformation Dilatometer, Dilatometry, ThermCon Scientific, laboratory instrument, DIWAN | Z18: https://www.thermconscientific.com/EN%2C7/dilatometer.html | AA18: 46257 | AB18: Product Team / Technical Reviewer | AC18: =IF(AND(O18<>"",P18<>"",R18<>"",T18<>"",X18<>"",Y18<>"",Z18<>"",AA18<>"",AB18<>""),IF(AND(Q18<>"",S18<>"",U18<>""),"Ready for approval","Content drafted - assets/specs pending"),IF(COUNTA(O18:AB18)=0,"Not started","In progress")) -> Content drafted - assets/specs pending | AD18: Official manufacturer category listing verified, but a model-specific technical page was not reliably indexed. Temperature range, deformation range, quench rate, atmosphere and sample geometry require manufacturer confirmation. Source reviewed 2026-08-23. Primary image and downloadable brochure assets remain open. | AG18: Availability, configuration and commercial supply are subject to confirmation by DIWAN and the manufacturer. | AH18: Lead time is confirmed in the formal quotation; do not publish a fixed delivery commitment. | AI18: Publish manufacturer documents only when public access and reuse are permitted; otherwise provide controlled access on request.
A19: =IF(B19=B18,A18,A18+1) -> 3 | B19: Dilatometry | C19: ThermCon Scientific | D19: Germany | E19: DIL-D Series Thermal Expansion Dilatometer | F19: /products/dilatometry | G19: One page per product category | H19: 46257 | I19: DIL-D Series Thermal Expansion Dilatometer | DIWAN Engineering & Technology Company | J19: dil-d-series-thermal-expansion-dilatometer | K19: The DIL-D Series provides high-resolution thermal-expansion and deformation measurement with programmable heating and controlled cooling for advanced materials research. | L19: DIL-D Series Thermal Expansion Dilatometer from ThermCon Scientific: key capabilities, technical specifications and applications. Request configuration advice and a quotation from DIWAN. | M19: Request technical information or a quote | N19: Draft complete - technical approval and assets pending | O19: ThermCon Scientific's DIL-D Series is a research dilatometer for precision measurement of dimensional change during heating and cooling. The platform supports controlled atmosphere, optional vacuum and programmable force for thermal-expansion and transformation studies. | P19: High-resolution displacement measurement; programmable heating and cooling; air, inert-gas and optional vacuum operation; adjustable sample load; software control and reporting. | Q19: Temperature range: approximately 20–1400°C; heating rate: 0.1–100°C/min; cooling rate: 0.1–50°C/min; sample diameter: 4–10 mm; sample length: up to 25 or 50 mm; adjustable load: 0.01–1 N; displacement range options: ±2.5 or ±5 mm. | R19: Metals, ceramics, glass, polymers and composites; CTE, shrinkage, phase-transformation and thermal-cycle deformation studies. | S19: https://www.thermconscientific.com/Resim/28501d4c16_20255912498747.jpg | T19: DIL-D Series Thermal Expansion Dilatometer from ThermCon Scientific | V19: No public downloadable brochure identified during review; provide documents on request after manufacturer rights and revision checks. | W19: DIL Series; DIL-Q; DIL-C; DIL Optical | X19: Dilatometry enquiry → website group enquiry form → category owner assignment | Y19: DIL-D Series Thermal Expansion Dilatometer, Dilatometry, ThermCon Scientific, laboratory instrument, DIWAN | Z19: https://www.thermconscientific.com/EN%2C213/dil-d-series-thermal-expansion-dilatometer.html | AA19: 46257 | AB19: Product Team / Technical Reviewer | AC19: =IF(AND(O19<>"",P19<>"",R19<>"",T19<>"",X19<>"",Y19<>"",Z19<>"",AA19<>"",AB19<>""),IF(AND(Q19<>"",S19<>"",U19<>""),"Ready for approval","Content drafted - assets/specs pending"),IF(COUNTA(O19:AB19)=0,"Not started","In progress")) -> Content drafted - assets/specs pending | AD19: Exact manufacturer product page verified; confirm final configuration, cooling system and vacuum options before publication. Source reviewed 2026-08-23. Primary image and downloadable brochure assets remain open. | AG19: Availability, configuration and commercial supply are subject to confirmation by DIWAN and the manufacturer. | AH19: Lead time is confirmed in the formal quotation; do not publish a fixed delivery commitment. | AI19: Publish manufacturer documents only when public access and reuse are permitted; otherwise provide controlled access on request.
A20: =IF(B20=B19,A19,A19+1) -> 3 | B20: Dilatometry | C20: ThermCon Scientific | D20: Germany | E20: DIL-C Series Cryogenic Thermal Expansion Dilatometer | F20: /products/dilatometry | G20: One page per product category | H20: 46257 | I20: DIL-C Series Cryogenic Thermal Expansion Dilatometer | DIWAN Engineering & Technology Company | J20: dil-c-series-cryogenic-thermal-expansion-dilatometer | K20: The DIL-C is ThermCon Scientific's cryogenic thermal-expansion dilatometer line for measuring dimensional change below and above ambient temperature. | L20: DIL-C Series Cryogenic Thermal Expansion Dilatometer from ThermCon Scientific: key capabilities, technical specifications and applications. Request configuration advice and a quotation from DIWAN. | M20: Request technical information or a quote | N20: Draft complete - technical approval and assets pending | O20: ThermCon Scientific lists the DIL-C as a cryogenic thermal-expansion dilatometer within its dilatometry portfolio. It is intended for materials whose expansion or contraction must be characterized across sub-ambient thermal cycles. | P20: Cryogenic thermal-expansion testing; dimensional-change and CTE measurement; programmed low-temperature cycling; configuration-specific cooling and atmosphere controls require confirmation. | R20: Metals, polymers, composites, electronic materials and research applications requiring low-temperature expansion and contraction data. | S20: https://www.thermconscientific.com/Resim/2d20793701_20244313184672.jpg | T20: DIL-C Series Cryogenic Thermal Expansion Dilatometer from ThermCon Scientific | V20: No public downloadable brochure identified during review; provide documents on request after manufacturer rights and revision checks. | W20: DIL-D; DIL Series; DIL-Q | X20: Dilatometry enquiry → website group enquiry form → category owner assignment | Y20: DIL-C Series Cryogenic Thermal Expansion Dilatometer, Dilatometry, ThermCon Scientific, laboratory instrument, DIWAN | Z20: https://www.thermconscientific.com/EN%2C7/dilatometer.html | AA20: 46257 | AB20: Product Team / Technical Reviewer | AC20: =IF(AND(O20<>"",P20<>"",R20<>"",T20<>"",X20<>"",Y20<>"",Z20<>"",AA20<>"",AB20<>""),IF(AND(Q20<>"",S20<>"",U20<>""),"Ready for approval","Content drafted - assets/specs pending"),IF(COUNTA(O20:AB20)=0,"Not started","In progress")) -> Content drafted - assets/specs pending | AD20: Official manufacturer category listing verified, but a model-specific technical page was not reliably indexed. Temperature range, cooling method, displacement resolution and sample geometry require manufacturer confirmation. Source reviewed 2026-08-23. Primary image and downloadable brochure assets remain open. | AG20: Availability, configuration and commercial supply are subject to confirmation by DIWAN and the manufacturer. | AH20: Lead time is confirmed in the formal quotation; do not publish a fixed delivery commitment. | AI20: Publish manufacturer documents only when public access and reuse are permitted; otherwise provide controlled access on request.
A21: =IF(B21=B20,A20,A20+1) -> 4 | B21: Material Testing | C21: ThermCon Scientific | D21: Germany | E21: CRUMPLEFLEX Fabric Flexing Tester | F21: /products/material-testing | G21: One page per product category | H21: 46257 | I21: CRUMPLEFLEX Fabric Flexing Tester | DIWAN Engineering & Technology Company | J21: crumpleflex-fabric-flexing-tester | K21: The CRUMPLEFLEX is listed by ThermCon Scientific as a fabric flexing tester for evaluating material durability under repeated crumpling or flexing cycles. | L21: CRUMPLEFLEX Fabric Flexing Tester from ThermCon Scientific: key capabilities, technical specifications and applications. Request configuration advice and a quotation from DIWAN. | M21: Request technical information or a quote | N21: Draft complete - technical approval and assets pending | O21: ThermCon Scientific presents CRUMPLEFLEX as a fabric flexing tester within its materials-testing content. The system is intended to assess how flexible sheet or fabric materials withstand repeated mechanical deformation. | P21: Repeated flexing or crumpling assessment; laboratory durability screening; method and fixture configuration require technical confirmation. | R21: Textiles, coated fabrics, flexible composites and sheet materials requiring comparative flex-durability testing. | T21: CRUMPLEFLEX Fabric Flexing Tester from ThermCon Scientific | V21: No public downloadable brochure identified during review; provide documents on request after manufacturer rights and revision checks. | W21: UL94 Horizontal/Vertical Flame Chamber | X21: Material Testing enquiry → website group enquiry form → category owner assignment | Y21: CRUMPLEFLEX Fabric Flexing Tester, Material Testing, ThermCon Scientific, laboratory instrument, DIWAN | Z21: https://www.thermconscientific.com/ | AA21: 46257 | AB21: Product Team / Technical Reviewer | AC21: =IF(AND(O21<>"",P21<>"",R21<>"",T21<>"",X21<>"",Y21<>"",Z21<>"",AA21<>"",AB21<>""),IF(AND(Q21<>"",S21<>"",U21<>""),"Ready for approval","Content drafted - assets/specs pending"),IF(COUNTA(O21:AB21)=0,"Not started","In progress")) -> Content drafted - assets/specs pending | AD21: Only the official manufacturer homepage/video listing was verified. Test method, standards, speed, stroke, specimen size and pass/fail criteria require manufacturer confirmation before a product page is published. Source reviewed 2026-08-23. Primary image and downloadable brochure assets remain open. | AG21: Availability, configuration and commercial supply are subject to confirmation by DIWAN and the manufacturer. | AH21: Lead time is confirmed in the formal quotation; do not publish a fixed delivery commitment. | AI21: Publish manufacturer documents only when public access and reuse are permitted; otherwise provide controlled access on request.
